<mujoco model="blockforge_pro">
  <compiler angle="radian" meshdir="assets" autolimits="true"/>

  <option integrator="implicitfast" impratio="10" cone="elliptic"/>

  <visual>
    <headlight diffuse="0.6 0.6 0.6" ambient="0.3 0.3 0.3" specular="0 0 0"/>
    <global azimuth="130" elevation="-25" offwidth="640" offheight="480"/>
  </visual>

  <default>
    <default class="panda">
      <material specular="0.5" shininess="0.25"/>
      <joint armature="0.1" damping="1" axis="0 0 1" range="-2.8973 2.8973"/>
      <general dyntype="none" biastype="affine" ctrlrange="-2.8973 2.8973" forcerange="-87 87"/>
    </default>
    <default class="panda/visual">
      <geom type="mesh" contype="0" conaffinity="0" group="2"/>
    </default>
    <default class="panda/collision">
      <geom type="mesh" group="3"/>
    </default>

    <!-- LEAP hand defaults at root level -->
    <geom solimp="0.999 0.999 0.001 0.0001 1" solref="0.0001 1" friction=".2"/>
    <position kp="3.0" kv="0.01"/>
    <joint damping="0.03" frictionloss="0.001"/>

    <default class="visual_leap">
      <geom group="1" type="mesh" contype="0" conaffinity="0" density="0" material="leap_black"/>
    </default>
    <default class="collision_leap">
      <geom material="leap_black"/>
    </default>
    <default class="tip">
      <geom type="mesh" mesh="tip" friction="0.5" material="leap_white"/>
    </default>
    <default class="thumb_tip">
      <geom type="mesh" mesh="thumb_tip" friction="0.5" material="leap_white"/>
    </default>
    <default class="mcp">
      <joint pos="0 0 0" axis="0 0 -1" limited="true" range="-0.314 2.23"/>
      <position ctrlrange="-0.314 2.23"/>
    </default>
    <default class="rot">
      <joint pos="0 0 0" axis="0 0 -1" limited="true" range="-1.047 1.047"/>
      <position ctrlrange="-1.047 1.047"/>
    </default>
    <default class="pip">
      <joint pos="0 0 0" axis="0 0 -1" limited="true" range="-0.506 1.885"/>
      <position ctrlrange="-0.506 1.885"/>
    </default>
    <default class="dip">
      <joint pos="0 0 0" axis="0 0 -1" limited="true" range="-0.366 2.042"/>
      <position ctrlrange="-0.366 2.042"/>
    </default>
    <default class="thumb_cmc">
      <joint pos="0 0 0" axis="0 0 -1" limited="true" range="-0.349 2.094"/>
      <position ctrlrange="-0.349 2.094"/>
    </default>
    <default class="thumb_axl">
      <joint pos="0 0 0" axis="0 0 -1" limited="true" range="-0.349 2.094"/>
      <position ctrlrange="-0.349 2.094"/>
    </default>
    <default class="thumb_mcp">
      <joint pos="0 0 0" axis="0 0 -1" limited="true" range="-0.47 2.443"/>
      <position ctrlrange="-0.47 2.443"/>
    </default>
    <default class="thumb_ipl">
      <joint pos="0 0 0" axis="0 0 -1" limited="true" range="-1.34 1.88"/>
      <position ctrlrange="-1.34 1.88"/>
    </default>
  </default>

  <asset>
    <texture type="skybox" builtin="gradient" rgb1="0.2 0.3 0.5" rgb2="0.05 0.05 0.1"
      width="512" height="3072"/>
    <texture type="2d" name="groundplane" builtin="checker" mark="edge"
      rgb1="0.25 0.28 0.35" rgb2="0.18 0.20 0.25" markrgb="0.4 0.4 0.5"
      width="300" height="300"/>
    <material name="groundplane" texture="groundplane" texuniform="true"
      texrepeat="6 6" reflectance="0.15"/>

    <material name="table_surface" rgba="0.55 0.45 0.35 1"/>
    <material name="table_leg" rgba="0.4 0.3 0.2 1"/>
    <material name="wall_grey" rgba="0.5 0.5 0.5 1"/>

    <material name="ring_small" rgba="0.95 0.3 0.3 1"/>
    <material name="ring_medium" rgba="0.2 0.8 0.3 1"/>
    <material name="ring_large" rgba="0.2 0.4 0.95 1"/>
    <material name="peg_metal" rgba="0.6 0.6 0.65 1"/>
    <material name="pegboard" rgba="0.45 0.4 0.35 1"/>

    <!-- Panda meshes -->
<material class="panda" name="white" rgba="1 1 1 1"/>
    <material class="panda" name="off_white" rgba="0.901961 0.921569 0.929412 1"/>
    <material class="panda" name="dark_grey" rgba="0.25 0.25 0.25 1"/>
    <material class="panda" name="green" rgba="0 1 0 1"/>
    <material class="panda" name="light_blue" rgba="0.039216 0.541176 0.780392 1"/>

    <!-- Collision meshes -->
    <mesh name="link0_c" file="link0.stl"/>
    <mesh name="link1_c" file="link1.stl"/>
    <mesh name="link2_c" file="link2.stl"/>
    <mesh name="link3_c" file="link3.stl"/>
    <mesh name="link4_c" file="link4.stl"/>
    <mesh name="link5_c0" file="link5_collision_0.obj"/>
    <mesh name="link5_c1" file="link5_collision_1.obj"/>
    <mesh name="link5_c2" file="link5_collision_2.obj"/>
    <mesh name="link6_c" file="link6.stl"/>
    <mesh name="link7_c" file="link7.stl"/>

    <!-- Visual meshes -->
    <mesh file="link0_0.obj"/>
    <mesh file="link0_1.obj"/>
    <mesh file="link0_2.obj"/>
    <mesh file="link0_3.obj"/>
    <mesh file="link0_4.obj"/>
    <mesh file="link0_5.obj"/>
    <mesh file="link0_7.obj"/>
    <mesh file="link0_8.obj"/>
    <mesh file="link0_9.obj"/>
    <mesh file="link0_10.obj"/>
    <mesh file="link0_11.obj"/>
    <mesh file="link1.obj"/>
    <mesh file="link2.obj"/>
    <mesh file="link3_0.obj"/>
    <mesh file="link3_1.obj"/>
    <mesh file="link3_2.obj"/>
    <mesh file="link3_3.obj"/>
    <mesh file="link4_0.obj"/>
    <mesh file="link4_1.obj"/>
    <mesh file="link4_2.obj"/>
    <mesh file="link4_3.obj"/>
    <mesh file="link5_0.obj"/>
    <mesh file="link5_1.obj"/>
    <mesh file="link5_2.obj"/>
    <mesh file="link6_0.obj"/>
    <mesh file="link6_1.obj"/>
    <mesh file="link6_2.obj"/>
    <mesh file="link6_3.obj"/>
    <mesh file="link6_4.obj"/>
    <mesh file="link6_5.obj"/>
    <mesh file="link6_6.obj"/>
    <mesh file="link6_7.obj"/>
    <mesh file="link6_8.obj"/>
    <mesh file="link6_9.obj"/>
    <mesh file="link6_10.obj"/>
    <mesh file="link6_11.obj"/>
    <mesh file="link6_12.obj"/>
    <mesh file="link6_13.obj"/>
    <mesh file="link6_14.obj"/>
    <mesh file="link6_15.obj"/>
    <mesh file="link6_16.obj"/>
    <mesh file="link7_0.obj"/>
    <mesh file="link7_1.obj"/>
    <mesh file="link7_2.obj"/>
    <mesh file="link7_3.obj"/>
    <mesh file="link7_4.obj"/>
    <mesh file="link7_5.obj"/>
    <mesh file="link7_6.obj"/>
    <mesh file="link7_7.obj"/>

    <!-- LEAP meshes -->
<material name="leap_black" rgba="0.2 0.2 0.2 1"/>
    <material name="leap_white" rgba="1 1 1 1"/>

    <mesh name="palm" file="palm_right.obj"/>
    <mesh name="base" file="base.obj"/>
    <mesh name="proximal" file="proximal.obj"/>
    <mesh name="medial" file="medial.obj"/>
    <mesh name="distal" file="distal.obj"/>
    <mesh name="tip" file="tip.obj"/>
    <mesh name="thumb_base" file="thumb_base.obj"/>
    <mesh name="thumb_proximal" file="thumb_proximal.obj"/>
    <mesh name="thumb_distal" file="thumb_distal.obj"/>
    <mesh name="thumb_tip" file="thumb_tip.obj"/>
  </asset>

  <worldbody>
    <light name="key" pos="2 0 2.5" dir="-0.5 0 -1" directional="false"
      diffuse="0.8 0.8 0.8" specular="0.3 0.3 0.3"/>
    <light name="fill" pos="-1 2 1.5" dir="0.5 -1 -0.5" directional="false"
      diffuse="0.4 0.4 0.5" specular="0 0 0"/>
    <geom name="floor" size="0 0 0.025" type="plane" material="groundplane"/>

    <!-- === FIXED BASE for Franka arm with LEAP HAND inside attachment === -->

    <body name="panda_base" pos="0.2 0 0">
      <light name="top" pos="0 0 2" mode="trackcom"/>
    <body name="link0" childclass="panda">
      <inertial mass="0.629769" pos="-0.041018 -0.00014 0.049974"
        fullinertia="0.00315 0.00388 0.004285 8.2904e-7 0.00015 8.2299e-6"/>
      <geom mesh="link0_0" material="off_white" class="panda/visual"/>
      <geom mesh="link0_1" material="dark_grey" class="panda/visual"/>
      <geom mesh="link0_2" material="off_white" class="panda/visual"/>
      <geom mesh="link0_3" material="dark_grey" class="panda/visual"/>
      <geom mesh="link0_4" material="off_white" class="panda/visual"/>
      <geom mesh="link0_5" material="dark_grey" class="panda/visual"/>
      <geom mesh="link0_7" material="white" class="panda/visual"/>
      <geom mesh="link0_8" material="white" class="panda/visual"/>
      <geom mesh="link0_9" material="dark_grey" class="panda/visual"/>
      <geom mesh="link0_10" material="off_white" class="panda/visual"/>
      <geom mesh="link0_11" material="white" class="panda/visual"/>
      <geom mesh="link0_c" class="panda/collision"/>
      <body name="link1" pos="0 0 0.333">
        <inertial mass="4.970684" pos="0.003875 0.002081 -0.04762"
          fullinertia="0.70337 0.70661 0.0091170 -0.00013900 0.0067720 0.019169"/>
        <joint name="joint1"/>
        <geom material="white" mesh="link1" class="panda/visual"/>
        <geom mesh="link1_c" class="panda/collision"/>
        <body name="link2" quat="1 -1 0 0">
          <inertial mass="0.646926" pos="-0.003141 -0.02872 0.003495"
            fullinertia="0.0079620 2.8110e-2 2.5995e-2 -3.925e-3 1.0254e-2 7.04e-4"/>
          <joint name="joint2" range="-1.7628 1.7628"/>
          <geom material="white" mesh="link2" class="panda/visual"/>
          <geom mesh="link2_c" class="panda/collision"/>
          <body name="link3" pos="0 -0.316 0" quat="1 1 0 0">
            <joint name="joint3"/>
            <inertial mass="3.228604" pos="2.7518e-2 3.9252e-2 -6.6502e-2"
              fullinertia="3.7242e-2 3.6155e-2 1.083e-2 -4.761e-3 -1.1396e-2 -1.2805e-2"/>
            <geom mesh="link3_0" material="white" class="panda/visual"/>
            <geom mesh="link3_1" material="white" class="panda/visual"/>
            <geom mesh="link3_2" material="white" class="panda/visual"/>
            <geom mesh="link3_3" material="dark_grey" class="panda/visual"/>
            <geom mesh="link3_c" class="panda/collision"/>
            <body name="link4" pos="0.0825 0 0" quat="1 1 0 0">
              <inertial mass="3.587895" pos="-5.317e-2 1.04419e-1 2.7454e-2"
                fullinertia="2.5853e-2 1.9552e-2 2.8323e-2 7.796e-3 -1.332e-3 8.641e-3"/>
              <joint name="joint4" range="-3.0718 -0.0698"/>
              <geom mesh="link4_0" material="white" class="panda/visual"/>
              <geom mesh="link4_1" material="white" class="panda/visual"/>
              <geom mesh="link4_2" material="dark_grey" class="panda/visual"/>
              <geom mesh="link4_3" material="white" class="panda/visual"/>
              <geom mesh="link4_c" class="panda/collision"/>
              <body name="link5" pos="-0.0825 0.384 0" quat="1 -1 0 0">
                <inertial mass="1.225946" pos="-1.1953e-2 4.1065e-2 -3.8437e-2"
                  fullinertia="3.5549e-2 2.9474e-2 8.627e-3 -2.117e-3 -4.037e-3 2.29e-4"/>
                <joint name="joint5"/>
                <geom mesh="link5_0" material="dark_grey" class="panda/visual"/>
                <geom mesh="link5_1" material="white" class="panda/visual"/>
                <geom mesh="link5_2" material="white" class="panda/visual"/>
                <geom mesh="link5_c0" class="panda/collision"/>
                <geom mesh="link5_c1" class="panda/collision"/>
                <geom mesh="link5_c2" class="panda/collision"/>
                <body name="link6" quat="1 1 0 0">
                  <inertial mass="1.666555" pos="6.0149e-2 -1.4117e-2 -1.0517e-2"
                    fullinertia="1.964e-3 4.354e-3 5.433e-3 1.09e-4 -1.158e-3 3.41e-4"/>
                  <joint name="joint6" range="-0.0175 3.7525"/>
                  <geom mesh="link6_0" material="off_white" class="panda/visual"/>
                  <geom mesh="link6_1" material="white" class="panda/visual"/>
                  <geom mesh="link6_2" material="dark_grey" class="panda/visual"/>
                  <geom mesh="link6_3" material="white" class="panda/visual"/>
                  <geom mesh="link6_4" material="white" class="panda/visual"/>
                  <geom mesh="link6_5" material="white" class="panda/visual"/>
                  <geom mesh="link6_6" material="white" class="panda/visual"/>
                  <geom mesh="link6_7" material="light_blue" class="panda/visual"/>
                  <geom mesh="link6_8" material="light_blue" class="panda/visual"/>
                  <geom mesh="link6_9" material="dark_grey" class="panda/visual"/>
                  <geom mesh="link6_10" material="dark_grey" class="panda/visual"/>
                  <geom mesh="link6_11" material="white" class="panda/visual"/>
                  <geom mesh="link6_12" material="green" class="panda/visual"/>
                  <geom mesh="link6_13" material="white" class="panda/visual"/>
                  <geom mesh="link6_14" material="dark_grey" class="panda/visual"/>
                  <geom mesh="link6_15" material="dark_grey" class="panda/visual"/>
                  <geom mesh="link6_16" material="white" class="panda/visual"/>
                  <geom mesh="link6_c" class="panda/collision"/>
                  <body name="link7" pos="0.088 0 0" quat="1 1 0 0">
                    <inertial mass="7.35522e-01" pos="1.0517e-2 -4.252e-3 6.1597e-2"
                      fullinertia="1.2516e-2 1.0027e-2 4.815e-3 -4.28e-4 -1.196e-3 -7.41e-4"/>
                    <joint name="joint7"/>
                    <geom mesh="link7_0" material="white" class="panda/visual"/>
                    <geom mesh="link7_1" material="dark_grey" class="panda/visual"/>
                    <geom mesh="link7_2" material="dark_grey" class="panda/visual"/>
                    <geom mesh="link7_3" material="dark_grey" class="panda/visual"/>
                    <geom mesh="link7_4" material="dark_grey" class="panda/visual"/>
                    <geom mesh="link7_5" material="dark_grey" class="panda/visual"/>
                    <geom mesh="link7_6" material="dark_grey" class="panda/visual"/>
                    <geom mesh="link7_7" material="white" class="panda/visual"/>
                    <geom mesh="link7_c" class="panda/collision"/>
                    <body name="attachment" pos="0 0 0.107" quat="0.3826834 0 0 0.9238795">
                      <body name="palm" pos="0 0 0.1" quat="0 1 0 0">
      <!-- palm -->
      <inertial pos="-0.049542 -0.042914 -0.010227" quat="0.565586 0.427629 -0.574956 0.408254" mass="0.237"
        diaginertia="0.000407345 0.000304759 0.000180736"/>
      <geom name="palm_visual" pos="-0.02 0.02575 -0.0347" quat="1 0 0 0" class="visual_leap" mesh="palm"/>
      <geom name="palm_collision_1" size="0.011 0.013 0.017" pos="-0.009 0.008 -0.011" type="box" class="collision_leap"/>
      <geom name="palm_collision_2" size="0.011 0.013 0.017" pos="-0.009 -0.037 -0.011" type="box" class="collision_leap"/>
      <geom name="palm_collision_3" size="0.011 0.013 0.017" pos="-0.009 -0.082 -0.011" type="box" class="collision_leap"/>
      <geom name="palm_collision_4" size="0.029 0.01 0.023" pos="-0.066 -0.078 -0.0115" quat="0.989016 0 0 -0.147806"
        type="box" class="collision_leap"/>
      <geom name="palm_collision_5" size="0.01 0.06 0.015" pos="-0.03 -0.035 -0.003" type="box" class="collision_leap"/>
      <geom name="palm_collision_6" size="0.005 0.06 0.01" pos="-0.032 -0.035 -0.024" quat="0.923956 0 0.382499 0"
        type="box" class="collision_leap"/>
      <geom name="palm_collision_7" size="0.012 0.058 0.023" pos="-0.048 -0.033 -0.0115" type="box" class="collision_leap"/>
      <geom name="palm_collision_8" size="0.022 0.026 0.023" pos="-0.078 -0.053 -0.0115" type="box" class="collision_leap"/>
      <geom name="palm_collision_9" size="0.002 0.018 0.017" pos="-0.098 -0.009 -0.006" type="box" class="collision_leap"/>
      <geom name="palm_collision_10" size="0.022 0.028 0.002" pos="-0.078 -0.003 0.01" type="box" class="collision_leap"/>

      <!-- index -->
      <body name="if_bs" pos="-0.007 0.023 -0.0187" quat="0.500003 0.5 0.5 -0.499997">
        <inertial pos="-0.022516 0.033882 0.016359" quat="0.388092 0.677951 -0.247713 0.573067" mass="0.044"
          diaginertia="1.74972e-05 1.61504e-05 7.21342e-06"/>
        <joint name="if_mcp" class="mcp"/>
        <geom name="if_bs_visual" pos="0.0084 0.0077 0.01465" quat="1 0 0 0" class="visual_leap" mesh="base"/>
        <geom name="if_bs_collision_1" size="0.01 0.003 0.017" pos="0 0.018 0.0147" type="box" class="collision_leap"/>
        <geom name="if_bs_collision_2" size="0.014 0.02 0.01" pos="-0.027 0.042 0.015" type="box" class="collision_leap"/>
        <geom name="if_bs_collision_3" size="0.017 0.003 0.01" pos="-0.0262 0.02 0.0146" type="box" class="collision_leap"/>
        <geom name="if_bs_collision_4" size="0.01 0.012 0.004" pos="-0.0295 0.035 0.029" type="box" class="collision_leap"/>
        <geom name="if_bs_collision_5" size="0.007 0.01 0.002" pos="0 0.005 0.03" type="box" class="collision_leap"/>
        <geom name="if_bs_collision_6" size="0.007 0.01 0.002" pos="0 0.005 -0.001" type="box" class="collision_leap"/>

        <body name="if_px" pos="-0.0122 0.0381 0.0145" quat="0.500003 -0.5 -0.499997 0.5">
          <inertial pos="0.0075 -0.0002 -0.011" quat="0 0.707107 0 0.707107" mass="0.032"
            diaginertia="4.8853e-06 4.3733e-06 3.0933e-06"/>
          <joint name="if_rot" class="rot"/>
          <geom name="if_px_visual" pos="0.0096 0.0002 0.0007" quat="0.500003 -0.5 -0.5 -0.499997" class="visual_leap"
            mesh="proximal"/>
          <geom name="if_px_collision" size="0.017 0.013 0.011" pos="0.0075 -0.0002 -0.011" type="box"
            class="collision_leap"/>

          <body name="if_md" pos="0.015 0.0143 -0.013" quat="0.500003 0.5 -0.5 0.499997">
            <inertial pos="0.0054215 -0.029148 0.015" quat="0.687228 0.687228 0.166487 0.166487" mass="0.037"
              diaginertia="8.28004e-06 8.1598e-06 5.39516e-06"/>
            <joint name="if_pip" class="pip"/>
            <geom name="if_md_visual" pos="0.0211 -0.0084 0.0097" quat="2.67949e-08 -1 0 0" class="visual_leap"
              mesh="medial"/>
            <geom name="if_md_collision_1" size="0.008 0.003 0.013" pos="0 -0.02 0.015" type="box" class="collision_leap"/>
            <geom name="if_md_collision_2" size="0.01 0.002 0.017" pos="0 -0.016 0.015" type="box" class="collision_leap"/>
            <geom name="if_md_collision_3" size="0.007 0.01 0.002" pos="0 -0.0045 0.03" type="box" class="collision_leap"/>
            <geom name="if_md_collision_4" size="0.007 0.01 0.002" pos="0 -0.0045 0" type="box" class="collision_leap"/>
            <geom name="if_md_collision_5" size="0.017 0.011 0.013" pos="0.0075 -0.035 0.015" type="box"
              class="collision_leap"/>

            <body name="if_ds" pos="0 -0.0361 0.0002">
              <inertial pos="-0.0008794 -0.027019 0.014594" quat="0.702905 0.710643 -0.0212937 -0.0214203" mass="0.016"
                diaginertia="3.71863e-06 3.02396e-06 1.6518e-06"/>
              <joint name="if_dip" class="dip"/>
              <geom name="if_ds_visual" pos="0.0132 -0.0061 0.0144" quat="2.67949e-08 1 0 0" class="visual_leap"
                mesh="distal"/>
              <geom name="if_ds_collision_1" size="0.01 0.003 0.015" pos="0 -0.017 0.015" type="box" class="collision_leap"/>
              <geom name="if_ds_collision_2" size="0.007 0.011 0.002" pos="0 -0.006 0.03" type="box" class="collision_leap"/>
              <geom name="if_ds_collision_3" size="0.007 0.011 0.002" pos="0 -0.006 -0.001" type="box"
                class="collision_leap"/>

              <geom name="if_tip" class="tip"/>
              <site name="if_tip_site" size="0.003"/>
            </body>
          </body>
        </body>
      </body>
      <!-- index -->

      <!-- middle -->
      <body name="mf_bs" pos="-0.0071 -0.0224 -0.0187" quat="0.500003 0.5 0.5 -0.499997">
        <inertial pos="-0.022516 0.033882 0.016359" quat="0.388092 0.677951 -0.247713 0.573067" mass="0.044"
          diaginertia="1.74972e-05 1.61504e-05 7.21342e-06"/>
        <joint name="mf_mcp" class="mcp"/>
        <geom name="mf_bs_visual" pos="0.0084 0.0077 0.01465" quat="1 0 0 0" class="visual_leap" mesh="base"/>
        <geom name="mf_bs_collision_1" size="0.01 0.003 0.017" pos="0 0.018 0.0147" type="box" class="collision_leap"/>
        <geom name="mf_bs_collision_2" size="0.014 0.02 0.01" pos="-0.027 0.042 0.015" type="box" class="collision_leap"/>
        <geom name="mf_bs_collision_3" size="0.017 0.003 0.01" pos="-0.0262 0.02 0.0146" type="box" class="collision_leap"/>
        <geom name="mf_bs_collision_4" size="0.01 0.012 0.004" pos="-0.0295 0.035 0.029" type="box" class="collision_leap"/>
        <geom name="mf_bs_collision_5" size="0.007 0.01 0.002" pos="0 0.005 0.03" type="box" class="collision_leap"/>
        <geom name="mf_bs_collision_6" size="0.007 0.01 0.002" pos="0 0.005 -0.001" type="box" class="collision_leap"/>

        <body name="mf_px" pos="-0.0122 0.0381 0.0145" quat="0.500003 -0.5 -0.499997 0.5">
          <inertial pos="0.0075 -0.0002 -0.011" quat="0 0.707107 0 0.707107" mass="0.032"
            diaginertia="4.8853e-06 4.3733e-06 3.0933e-06"/>
          <joint name="mf_rot" class="rot"/>
          <geom name="mf_px_visual" pos="0.0096 0.0003 0.0007" quat="0.500003 -0.5 -0.5 -0.499997" class="visual_leap"
            mesh="proximal"/>
          <geom name="mf_px_collision" size="0.017 0.013 0.011" pos="0.0075 -0.0002 -0.011" type="box"
            class="collision_leap"/>

          <body name="mf_md" pos="0.015 0.0143 -0.013" quat="0.500003 0.5 -0.5 0.499997">
            <inertial pos="0.0054215 -0.029148 0.015" quat="0.687228 0.687228 0.166487 0.166487" mass="0.037"
              diaginertia="8.28004e-06 8.1598e-06 5.39516e-06"/>
            <joint name="mf_pip" class="pip"/>
            <geom name="mf_md_visual" pos="0.0211 -0.0084 0.0097" quat="1.32679e-06 -1 0 0" class="visual_leap"
              mesh="medial"/>
            <geom name="mf_md_collision_1" size="0.008 0.003 0.013" pos="0 -0.02 0.015" type="box" class="collision_leap"/>
            <geom name="mf_md_collision_2" size="0.01 0.002 0.017" pos="0 -0.016 0.015" type="box" class="collision_leap"/>
            <geom name="mf_md_collision_3" size="0.007 0.01 0.002" pos="0 -0.0045 0.03" type="box" class="collision_leap"/>
            <geom name="mf_md_collision_4" size="0.007 0.01 0.002" pos="0 -0.0045 0" type="box" class="collision_leap"/>
            <geom name="mf_md_collision_5" size="0.017 0.011 0.013" pos="0.0075 -0.035 0.015" type="box"
              class="collision_leap"/>

            <body name="mf_ds" pos="0 -0.0361 0.0002">
              <inertial pos="-0.0008794 -0.027019 0.014594" quat="0.702905 0.710643 -0.0212937 -0.0214203" mass="0.016"
                diaginertia="3.71863e-06 3.02396e-06 1.6518e-06"/>
              <joint name="mf_dip" class="dip"/>
              <geom name="mf_ds_visual" pos="0.0132 -0.0061 0.0145" quat="1.32679e-06 1 0 0" class="visual_leap"
                mesh="distal"/>
              <geom name="mf_ds_collision_1" size="0.01 0.003 0.015" pos="0 -0.017 0.015" type="box" class="collision_leap"/>
              <geom name="mf_ds_collision_2" size="0.007 0.011 0.002" pos="0 -0.006 0.03" type="box" class="collision_leap"/>
              <geom name="mf_ds_collision_3" size="0.007 0.011 0.002" pos="0 -0.006 -0.001" type="box"
                class="collision_leap"/>

              <geom name="mf_tip" class="tip"/>
              <site name="mf_tip_site" size="0.003"/>
            </body>
          </body>
        </body>
      </body>
      <!-- middle -->

      <!-- ring -->
      <body name="rf_bs" pos="-0.00709 -0.0678 -0.0187" quat="0.500003 0.5 0.5 -0.499997">
        <inertial pos="-0.022516 0.033882 0.016359" quat="0.388092 0.677951 -0.247713 0.573067" mass="0.044"
          diaginertia="1.74972e-05 1.61504e-05 7.21342e-06"/>
        <joint name="rf_mcp" class="mcp"/>
        <geom name="rf_bs_visual" pos="0.0084 0.0077 0.01465" quat="1 0 0 0" class="visual_leap" mesh="base"/>
        <geom name="rf_bs_collision_1" size="0.01 0.003 0.017" pos="0 0.018 0.0147" type="box" class="collision_leap"/>
        <geom name="rf_bs_collision_2" size="0.014 0.02 0.01" pos="-0.027 0.042 0.015" type="box" class="collision_leap"/>
        <geom name="rf_bs_collision_3" size="0.017 0.003 0.01" pos="-0.0262 0.02 0.0146" type="box" class="collision_leap"/>
        <geom name="rf_bs_collision_4" size="0.01 0.012 0.004" pos="-0.0295 0.035 0.029" type="box" class="collision_leap"/>
        <geom name="rf_bs_collision_5" size="0.007 0.01 0.002" pos="0 0.005 0.03" type="box" class="collision_leap"/>
        <geom name="rf_bs_collision_6" size="0.007 0.01 0.002" pos="0 0.005 -0.001" type="box" class="collision_leap"/>

        <body name="rf_px" pos="-0.0122 0.0381 0.0145" quat="0.500003 -0.5 -0.499997 0.5">
          <inertial pos="0.0075 -0.0002 -0.011" quat="0 0.707107 0 0.707107" mass="0.032"
            diaginertia="4.8853e-06 4.3733e-06 3.0933e-06"/>
          <joint name="rf_rot" class="rot"/>
          <geom name="rf_px_visual" pos="0.0096 0.0003 0.0007" quat="0.500003 -0.5 -0.5 -0.499997" class="visual_leap"
            mesh="proximal"/>
          <geom name="rf_px_collision" size="0.017 0.013 0.011" pos="0.0075 -0.0002 -0.011" type="box"
            class="collision_leap"/>

          <body name="rf_md" pos="0.015 0.0143 -0.013" quat="0.500003 0.5 -0.5 0.499997">
            <inertial pos="0.0054215 -0.029148 0.015" quat="0.687228 0.687228 0.166487 0.166487" mass="0.037"
              diaginertia="8.28004e-06 8.1598e-06 5.39516e-06"/>
            <joint name="rf_pip" class="pip"/>
            <geom name="rf_md_visual" pos="0.0211 -0.0084 0.0097" quat="1.32679e-06 -1 0 0" class="visual_leap"
              mesh="medial"/>
            <geom name="rf_md_collision_1" size="0.008 0.003 0.013" pos="0 -0.02 0.015" type="box" class="collision_leap"/>
            <geom name="rf_md_collision_2" size="0.01 0.002 0.017" pos="0 -0.016 0.015" type="box" class="collision_leap"/>
            <geom name="rf_md_collision_3" size="0.007 0.01 0.002" pos="0 -0.0045 0.03" type="box" class="collision_leap"/>
            <geom name="rf_md_collision_4" size="0.007 0.01 0.002" pos="0 -0.0045 0" type="box" class="collision_leap"/>
            <geom name="rf_md_collision_5" size="0.017 0.011 0.013" pos="0.0075 -0.035 0.015" type="box"
              class="collision_leap"/>

            <body name="rf_ds" pos="0 -0.03609 0.0002">
              <inertial pos="-0.0008794 -0.027019 0.014594" quat="0.702905 0.710643 -0.0212937 -0.0214203" mass="0.016"
                diaginertia="3.71863e-06 3.02396e-06 1.6518e-06"/>
              <joint name="rf_dip" class="dip"/>
              <geom name="rf_ds_visual" pos="0.0132 -0.0061 0.0145" quat="1.32679e-06 1 0 0" class="visual_leap"
                mesh="distal"/>
              <geom name="rf_ds_collision_1" size="0.01 0.003 0.015" pos="0 -0.017 0.015" type="box" class="collision_leap"/>
              <geom name="rf_ds_collision_2" size="0.007 0.011 0.002" pos="0 -0.006 0.03" type="box" class="collision_leap"/>
              <geom name="rf_ds_collision_3" size="0.007 0.011 0.002" pos="0 -0.006 -0.001" type="box"
                class="collision_leap"/>

              <geom name="rf_tip" class="tip"/>
              <site name="rf_tip_site" size="0.003"/>
            </body>
          </body>
        </body>
      </body>
      <!-- ring -->

      <!-- thumb -->
      <body name="th_mp" pos="-0.0693 -0.0012 -0.0216" quat="0.707109 0 0.707105 0">
        <inertial pos="0.0075 -0.0002 -0.011" quat="0 0.707107 0 0.707107" mass="0.032"
          diaginertia="4.8853e-06 4.3733e-06 3.0933e-06"/>
        <joint name="th_cmc" class="thumb_cmc"/>
        <geom name="th_mp_visual" pos="-0.0053 0.0003 0.00078" quat="0.500003 -0.5 -0.5 -0.499997" class="visual_leap"
          mesh="proximal"/>
        <geom name="th_mp_collision" size="0.017 0.013 0.011" pos="-0.0075 -0.0002 -0.011" type="box"
          class="collision_leap"/>

        <body name="th_bs" pos="0 0.0143 -0.013" quat="0.500003 0.5 -0.5 0.499997">
          <inertial pos="0 0 -0.0070806" quat="0.707107 0.707107 0 0" mass="0.003"
            diaginertia="6.1932e-07 5.351e-07 2.1516e-07"/>
          <joint name="th_axl" class="thumb_axl"/>
          <geom name="th_bs_visual" pos="0.01196 0 -0.0158" quat="0.707109 0.707105 0 0" class="visual_leap"
            mesh="thumb_base"/>
          <geom name="th_bs_collision_1" size="0.009 0.0165 0.002" pos="0 0 -0.0015" type="box" class="collision_leap"/>
          <geom name="th_bs_collision_2" size="0.007 0.002 0.01" pos="0 -0.015 -0.013" type="box" class="collision_leap"/>
          <geom name="th_bs_collision_3" size="0.007 0.002 0.01" pos="0 0.015 -0.013" type="box" class="collision_leap"/>

          <body name="th_px" pos="0 0.0145 -0.017" quat="0.707109 -0.707105 0 0">
            <inertial pos="-0.0020593 0.015912 -0.013733" quat="0.698518 0.697382 -0.104933 0.121324" mass="0.038"
              diaginertia="9.87104e-06 9.32653e-06 4.36203e-06"/>
            <joint name="th_mcp" class="thumb_mcp"/>
            <geom name="th_px_visual" pos="0.0439 0.0579 -0.0086" quat="1 0 0 0" class="visual_leap" mesh="thumb_proximal"/>
            <geom name="th_px_collision_1" size="0.01 0.02 0.012" pos="0 0.0105 -0.014" type="box" class="collision_leap"/>
            <geom name="th_px_collision_2" size="0.01 0.002 0.016" pos="0 0.031 -0.015" type="box" class="collision_leap"/>
            <geom name="th_px_collision_3" size="0.007 0.01 0.002" pos="0 0.042 0.001" type="box" class="collision_leap"/>
            <geom name="th_px_collision_4" size="0.007 0.01 0.002" pos="0 0.042 -0.029" type="box" class="collision_leap"/>
            <geom name="th_px_collision_5" size="0.005 0.012 0.009" pos="-0.0135 0.0175 -0.011656" type="box"
              class="collision_leap"/>

            <body name="th_ds" pos="0 0.0466 0.0002" quat="1.32679e-06 0 0 1">
              <inertial pos="0.00096191 -0.024203 -0.014419" quat="0.35287 0.311272 -0.632839 0.614904" mass="0.049"
                diaginertia="2.08591e-05 2.0402e-05 4.71335e-06"/>
              <joint name="th_ipl" class="thumb_ipl"/>
              <geom name="th_ds_visual" pos="0.0625 0.0784 0.0489" quat="1 0 0 0" class="visual_leap" mesh="thumb_distal"/>
              <geom name="th_ds_collision_1" size="0.01 0.018 0.012" pos="0 -0.0085 -0.015" type="box"
                class="collision_leap"/>
              <geom name="th_ds_collision_2" size="0.01 0.002 0.015" pos="0 -0.029 -0.014" type="box"
                class="collision_leap"/>
              <geom name="th_ds_collision_3" size="0.004 0.012 0.009" pos="0.015 -0.0175 -0.0115" type="box"
                class="collision_leap"/>

              <geom name="th_tip" class="thumb_tip"/>
              <site name="th_tip_site" size="0.003"/>
            </body>
          </body>
        </body>
      </body>
      <!-- thumb -->
    </body>
    <!-- palm -->
                    </body>
                  </body>
                </body>
              </body>
            </body>
          </body>
        </body>
      </body>
    </body>
    </body>

    <!-- (LEAP hand body tree is injected inside the Panda attachment body via replace below) -->

    <!-- Table + task objects -->
    <body name="table" pos="0.35 -0.15 0.0">
      <geom name="table_top" type="box" size="0.4 0.35 0.02" pos="0 0 0.72" material="table_surface"/>
      <geom name="leg_fl" type="cylinder" size="0.025 0.35" pos="-0.3 -0.25 0.37" material="table_leg"/>
      <geom name="leg_fr" type="cylinder" size="0.025 0.35" pos="0.3 -0.25 0.37" material="table_leg"/>
      <geom name="leg_bl" type="cylinder" size="0.025 0.35" pos="-0.3 0.25 0.37" material="table_leg"/>
      <geom name="leg_br" type="cylinder" size="0.025 0.35" pos="0.3 0.25 0.37" material="table_leg"/>
    </body>

    <!-- 3 demonstration pegs at different positions (within Franka reach ~0.85m) -->
    <geom name="post_a" type="cylinder" size="0.02 0.10" pos="0.38 0.02 0.65" material="ring_small"/>
    <geom name="post_b" type="cylinder" size="0.02 0.10" pos="0.32 0.02 0.65" material="ring_medium"/>
    <geom name="post_c" type="cylinder" size="0.02 0.10" pos="0.26 0.02 0.65" material="ring_large"/>

    <site name="peg_small_top" type="sphere" size="0.008" pos="0.38 0.02 0.70" rgba="0.95 0.3 0.3 0.6"/>
    <site name="peg_medium_top" type="sphere" size="0.008" pos="0.32 0.02 0.70" rgba="0.2 0.8 0.3 0.6"/>
    <site name="peg_large_top" type="sphere" size="0.008" pos="0.26 0.02 0.70" rgba="0.2 0.4 0.95 0.6"/>

    <!-- Containment walls -->
    <geom name="wall_left" type="box" size="0.02 0.35 0.12" pos="-0.05 -0.15 0.80" material="wall_grey"/>
    <geom name="wall_right" type="box" size="0.02 0.35 0.12" pos="0.75 -0.15 0.80" material="wall_grey"/>
    <geom name="wall_back" type="box" size="0.42 0.02 0.12" pos="0.35 0.2 0.80" material="wall_grey"/>

    <camera name="overhead" pos="0.35 -0.15 1.4" xyaxes="1 0 0 0 1 0" mode="fixed"/>
    <camera name="front" pos="0.35 -0.85 1.1" xyaxes="1 0 0 0 0.4 0.916" mode="fixed"/>
    <camera name="closeup" pos="0.35 -0.35 1.0" xyaxes="1 0 0 0 0.6 0.8" mode="fixed"/>
  </worldbody>

<actuator>
<general class="panda" name="actuator1" joint="joint1" gainprm="4500" biasprm="0 -4500 -450"/>
    <general class="panda" name="actuator2" joint="joint2" gainprm="4500" biasprm="0 -4500 -450"
      ctrlrange="-1.7628 1.7628"/>
    <general class="panda" name="actuator3" joint="joint3" gainprm="3500" biasprm="0 -3500 -350"/>
    <general class="panda" name="actuator4" joint="joint4" gainprm="3500" biasprm="0 -3500 -350"
      ctrlrange="-3.0718 -0.0698"/>
    <general class="panda" name="actuator5" joint="joint5" gainprm="2000" biasprm="0 -2000 -200" forcerange="-12 12"/>
    <general class="panda" name="actuator6" joint="joint6" gainprm="2000" biasprm="0 -2000 -200" forcerange="-12 12"
      ctrlrange="-0.0175 3.7525"/>
    <general class="panda" name="actuator7" joint="joint7" gainprm="2000" biasprm="0 -2000 -200" forcerange="-12 12"/>
  </actuator>
<actuator>
<!-- index -->
    <position name="if_mcp_act" joint="if_mcp" class="mcp"/>
    <position name="if_rot_act" joint="if_rot" class="rot"/>
    <position name="if_pip_act" joint="if_pip" class="pip"/>
    <position name="if_dip_act" joint="if_dip" class="dip"/>

    <!-- middle -->
    <position name="mf_mcp_act" joint="mf_mcp" class="mcp"/>
    <position name="mf_rot_act" joint="mf_rot" class="rot"/>
    <position name="mf_pip_act" joint="mf_pip" class="pip"/>
    <position name="mf_dip_act" joint="mf_dip" class="dip"/>

    <!-- ring -->
    <position name="rf_mcp_act" joint="rf_mcp" class="mcp"/>
    <position name="rf_rot_act" joint="rf_rot" class="rot"/>
    <position name="rf_pip_act" joint="rf_pip" class="pip"/>
    <position name="rf_dip_act" joint="rf_dip" class="dip"/>

    <!-- thumb -->
    <position name="th_cmc_act" joint="th_cmc" class="thumb_cmc"/>
    <position name="th_axl_act" joint="th_axl" class="thumb_axl"/>
    <position name="th_mcp_act" joint="th_mcp" class="thumb_mcp"/>
    <position name="th_ipl_act" joint="th_ipl" class="thumb_ipl"/>
  </actuator>

  <sensor>
    <!-- LEAP finger sensors -->
    <!-- index -->
    <jointpos name="if_mcp_sensor" joint="if_mcp"/>
    <jointpos name="if_rot_sensor" joint="if_rot"/>
    <jointpos name="if_pip_sensor" joint="if_pip"/>
    <jointpos name="if_dip_sensor" joint="if_dip"/>

    <!-- middle -->
    <jointpos name="mf_mcp_sensor" joint="mf_mcp"/>
    <jointpos name="mf_rot_sensor" joint="mf_rot"/>
    <jointpos name="mf_pip_sensor" joint="mf_pip"/>
    <jointpos name="mf_dip_sensor" joint="mf_dip"/>

    <!-- ring -->
    <jointpos name="rf_mcp_sensor" joint="rf_mcp"/>
    <jointpos name="rf_rot_sensor" joint="rf_rot"/>
    <jointpos name="rf_pip_sensor" joint="rf_pip"/>
    <jointpos name="rf_dip_sensor" joint="rf_dip"/>

    <!-- thumb -->
    <jointpos name="th_cmc_sensor" joint="th_cmc"/>
    <jointpos name="th_axl_sensor" joint="th_axl"/>
    <jointpos name="th_mcp_sensor" joint="th_mcp"/>
    <jointpos name="th_ipl_sensor" joint="th_ipl"/>
    <!-- Peg target sensors -->
    <framepos name="peg_small_sensor" objtype="site" objname="peg_small_top"/>
    <framepos name="peg_medium_sensor" objtype="site" objname="peg_medium_top"/>
    <framepos name="peg_large_sensor" objtype="site" objname="peg_large_top"/>
    <!-- Fingertip touch -->
    <touch name="if_tip_touch" site="if_tip_site"/>
    <touch name="mf_tip_touch" site="mf_tip_site"/>
    <touch name="rf_tip_touch" site="rf_tip_site"/>
    <touch name="th_tip_touch" site="th_tip_site"/>
    <force name="if_tip_force" site="if_tip_site"/>
    <force name="mf_tip_force" site="mf_tip_site"/>
    <force name="rf_tip_force" site="rf_tip_site"/>
    <force name="th_tip_force" site="th_tip_site"/>
  </sensor>

  <contact>
    <exclude body1="link0" body2="link1"/>
    <!-- filter the palm from all other finger bodies except the tips -->
    <exclude body1="palm" body2="if_bs"/>
    <exclude body1="palm" body2="mf_bs"/>
    <exclude body1="palm" body2="rf_bs"/>
    <exclude body1="palm" body2="th_mp"/>

    <exclude body1="palm" body2="if_px"/>
    <exclude body1="palm" body2="mf_px"/>
    <exclude body1="palm" body2="rf_px"/>
    <exclude body1="palm" body2="th_bs"/>

    <exclude body1="palm" body2="if_md"/>
    <exclude body1="palm" body2="mf_md"/>
    <exclude body1="palm" body2="rf_md"/>
    <exclude body1="palm" body2="th_px"/>

    <!-- none of the base fingertip geoms can touch each other -->
    <exclude body1="if_bs" body2="mf_bs"/>
    <exclude body1="if_bs" body2="rf_bs"/>
    <exclude body1="mf_bs" body2="rf_bs"/>

    <exclude body1="th_mp" body2="if_bs"/>
    <exclude body1="th_mp" body2="mf_bs"/>
    <exclude body1="th_mp" body2="rf_bs"/>
  </contact>

</mujoco>